2020-08-26 07:05 INFO	Connecting to the server...
2020-08-26 07:05 SUCCESS	Connected to server successfully!
2020-08-26 07:05 INFO	GetWebConn -> 845324058 => 当前已存在活动的WebSocket 已为您切换当前Socket
2020-08-26 07:05 INFO	GroupMsg ->  {'FromGroupId': 959562190, 'FromGroupName': '测试群', 'FromUserId': 2450459910, 'FromNickName': '凤飞翱翔兮丷', 'Content': '赞我', 'MsgType': 'TextMsg', 'MsgTime': 1598450733, 'MsgSeq': 5725, 'MsgRandom': 3813401787, 'RedBaginfo': None}
2020-08-26 07:05 ERROR	An error has been caught in function '_invoke_callbacks', process 'MainProcess' (10168), thread 'ThreadPoolExecutor-0_4' (139706855565056):
Traceback (most recent call last):

  File "/usr/lib/python3.6/threading.py", line 884, in _bootstrap
    self._bootstrap_inner()
    │    └ <function Thread._bootstrap_inner at 0x7f10175db0d0>
    └ <Thread(ThreadPoolExecutor-0_4, started daemon 139706855565056)>
  File "/usr/lib/python3.6/threading.py", line 916, in _bootstrap_inner
    self.run()
    │    └ <function Thread.run at 0x7f10175d8e18>
    └ <Thread(ThreadPoolExecutor-0_4, started daemon 139706855565056)>
  File "/usr/lib/python3.6/threading.py", line 864, in run
    self._target(*self._args, **self._kwargs)
    │    │        │    │        │    └ {}
    │    │        │    │        └ <Thread(ThreadPoolExecutor-0_4, started daemon 139706855565056)>
    │    │        │    └ (<weakref at 0x7f1011804a48; to 'ThreadPoolExecutor' at 0x7f10117f4780>, <queue.Queue object at 0x7f10117f4898>)
    │    │        └ <Thread(ThreadPoolExecutor-0_4, started daemon 139706855565056)>
    │    └ <function _worker at 0x7f10155ad6a8>
    └ <Thread(ThreadPoolExecutor-0_4, started daemon 139706855565056)>
  File "/usr/lib/python3.6/concurrent/futures/thread.py", line 69, in _worker
    work_item.run()
    │         └ <function _WorkItem.run at 0x7f10155ad7b8>
    └ <concurrent.futures.thread._WorkItem object at 0x7f1010584320>
  File "/usr/lib/python3.6/concurrent/futures/thread.py", line 58, in run
    self.future.set_exception(exc)
    │    │      │             └ FileNotFoundError(2, 'No such file or directory')
    │    │      └ <function Future.set_exception at 0x7f1015628510>
    │    └ <Future at 0x7f1010584198 state=finished raised FileNotFoundError>
    └ <concurrent.futures.thread._WorkItem object at 0x7f1010584320>
  File "/usr/lib/python3.6/concurrent/futures/_base.py", line 534, in set_exception
    self._invoke_callbacks()
    │    └ <function Future._invoke_callbacks at 0x7f1015627e18>
    └ <Future at 0x7f1010584198 state=finished raised FileNotFoundError>
> File "/usr/lib/python3.6/concurrent/futures/_base.py", line 324, in _invoke_callbacks
    callback(self)
    │        └ <Future at 0x7f1010584198 state=finished raised FileNotFoundError>
    └ <bound method IOTBOT.__thread_pool_callback of IOTBOT <845324058> <host-http://127.0.0.1> <port-8888>>

  File "/usr/local/lib/python3.6/dist-packages/iotbot/client.py", line 320, in __thread_pool_callback
    raise worker_exception
          └ FileNotFoundError(2, 'No such file or directory')

  File "/usr/lib/python3.6/concurrent/futures/thread.py", line 56, in run
    result = self.fn(*self.args, **self.kwargs)
             │    │   │    │       │    └ {}
             │    │   │    │       └ <concurrent.futures.thread._WorkItem object at 0x7f1010584320>
             │    │   │    └ (<iotbot.model.GroupMsg object at 0x7f1010584208>,)
             │    │   └ <concurrent.futures.thread._WorkItem object at 0x7f1010584320>
             │    └ <function not_botself.<locals>.inner at 0x7f10158da048>
             └ <concurrent.futures.thread._WorkItem object at 0x7f1010584320>

  File "/usr/local/lib/python3.6/dist-packages/iotbot/decorators.py", line 49, in inner
    return func(ctx)
           │    └ <iotbot.model.GroupMsg object at 0x7f1010584208>
           └ <function receive_group_msg at 0x7f10158ccd08>

  File "/root/pyopq/plugins/bot_likeme.py", line 43, in receive_group_msg
    save(nowTime,ctx.FromUserId)
    │    │       │   └ 2450459910
    │    │       └ <iotbot.model.GroupMsg object at 0x7f1010584208>
    │    └ 1598450734.1668215
    └ <function save at 0x7f10158da1e0>

  File "/root/pyopq/plugins/bot_likeme.py", line 78, in save
    with open(fullPath, 'w', encoding='utf-8') as f:
              └ './resources/zan/date/2450459910.json'

FileNotFoundError: [Errno 2] No such file or directory: './resources/zan/date/2450459910.json'
2020-08-26 07:05 INFO	GroupMsg ->  {'FromGroupId': 959562190, 'FromGroupName': '测试群', 'FromUserId': 845324058, 'FromNickName': '凤飞翱翔兮丷🤖', 'Content': '{"Content":"@凤飞翱翔兮丷 正在赞~~请稍等，大概花费50s左右","UserID":[2450459910]}', 'MsgType': 'AtMsg', 'MsgTime': 1598450734, 'MsgSeq': 5726, 'MsgRandom': 1598450734, 'RedBaginfo': None}
